2025-07-23 17:42:20,323 django.request WARNING  Not Found: /favicon.ico
2025-07-23 17:42:20,323 django.server WARNING  "GET /favicon.ico HTTP/1.1" 404 179
2025-07-23 17:42:54,868 django.request ERROR    Internal Server Error: /
Traceback (most recent call last):
  File "C:\Users\SAMURAI\PycharmProjects\soc_reports\.venv\Lib\site-packages\django\core\handlers\exception.py", line 55, in inner
    response = get_response(request)
  File "C:\Users\SAMURAI\PycharmProjects\soc_reports\.venv\Lib\site-packages\django\core\handlers\base.py", line 197, in _get_response
    response = wrapped_callback(request, *callback_args, **callback_kwargs)
  File "C:\Users\SAMURAI\PycharmProjects\soc_reports\reports\views.py", line 51, in report_create_view
    report.user = request.user
    ^^^^^^^^^^^
  File "C:\Users\SAMURAI\PycharmProjects\soc_reports\.venv\Lib\site-packages\django\db\models\fields\related_descriptors.py", line 288, in __set__
    raise ValueError(
    ...<7 lines>...
    )
ValueError: Cannot assign "<SimpleLazyObject: <django.contrib.auth.models.AnonymousUser object at 0x000002AC341C9FD0>>": "Report.user" must be a "CustomUser" instance.
2025-07-23 17:42:54,947 django.server ERROR    "POST / HTTP/1.1" 500 145
2025-07-23 17:43:18,734 django.request ERROR    Internal Server Error: /admin/db_logger/statuslog/
Traceback (most recent call last):
  File "C:\Users\SAMURAI\PycharmProjects\soc_reports\.venv\Lib\site-packages\django\db\backends\utils.py", line 105, in _execute
    return self.cursor.execute(sql, params)
           ~~~~~~~~~~~~~~~~~~~^^^^^^^^^^^^^
  File "C:\Users\SAMURAI\PycharmProjects\soc_reports\.venv\Lib\site-packages\django\db\backends\sqlite3\base.py", line 360, in execute
    return super().execute(query, params)
           ~~~~~~~~~~~~~~~^^^^^^^^^^^^^^^
sqlite3.OperationalError: no such table: db_logger_statuslog

The above exception was the direct cause of the following exception:

Traceback (most recent call last):
  File "C:\Users\SAMURAI\PycharmProjects\soc_reports\.venv\Lib\site-packages\django\core\handlers\exception.py", line 55, in inner
    response = get_response(request)
  File "C:\Users\SAMURAI\PycharmProjects\soc_reports\.venv\Lib\site-packages\django\core\handlers\base.py", line 197, in _get_response
    response = wrapped_callback(request, *callback_args, **callback_kwargs)
  File "C:\Users\SAMURAI\PycharmProjects\soc_reports\.venv\Lib\site-packages\django\contrib\admin\options.py", line 719, in wrapper
    return self.admin_site.admin_view(view)(*args, **kwargs)
           ~~~~~~~~~~~~~~~~~~~~~~~~~~~~~~~~^^^^^^^^^^^^^^^^^
  File "C:\Users\SAMURAI\PycharmProjects\soc_reports\.venv\Lib\site-packages\django\utils\decorators.py", line 192, in _view_wrapper
    result = _process_exception(request, e)
  File "C:\Users\SAMURAI\PycharmProjects\soc_reports\.venv\Lib\site-packages\django\utils\decorators.py", line 190, in _view_wrapper
    response = view_func(request, *args, **kwargs)
  File "C:\Users\SAMURAI\PycharmProjects\soc_reports\.venv\Lib\site-packages\django\views\decorators\cache.py", line 80, in _view_wrapper
    response = view_func(request, *args, **kwargs)
  File "C:\Users\SAMURAI\PycharmProjects\soc_reports\.venv\Lib\site-packages\django\contrib\admin\sites.py", line 246, in inner
    return view(request, *args, **kwargs)
  File "C:\Users\SAMURAI\PycharmProjects\soc_reports\.venv\Lib\site-packages\django\utils\decorators.py", line 48, in _wrapper
    return bound_method(*args, **kwargs)
  File "C:\Users\SAMURAI\PycharmProjects\soc_reports\.venv\Lib\site-packages\django\utils\decorators.py", line 192, in _view_wrapper
    result = _process_exception(request, e)
  File "C:\Users\SAMURAI\PycharmProjects\soc_reports\.venv\Lib\site-packages\django\utils\decorators.py", line 190, in _view_wrapper
    response = view_func(request, *args, **kwargs)
  File "C:\Users\SAMURAI\PycharmProjects\soc_reports\.venv\Lib\site-packages\django\contrib\admin\options.py", line 2024, in changelist_view
    cl = self.get_changelist_instance(request)
  File "C:\Users\SAMURAI\PycharmProjects\soc_reports\.venv\Lib\site-packages\django\contrib\admin\options.py", line 867, in get_changelist_instance
    return ChangeList(
        request,
    ...<12 lines>...
        self.search_help_text,
    )
  File "C:\Users\SAMURAI\PycharmProjects\soc_reports\.venv\Lib\site-packages\django\contrib\admin\views\main.py", line 146, in __init__
    self.get_results(request)
    ~~~~~~~~~~~~~~~~^^^^^^^^^
  File "C:\Users\SAMURAI\PycharmProjects\soc_reports\.venv\Lib\site-packages\django\contrib\admin\views\main.py", line 313, in get_results
    result_count = paginator.count
                   ^^^^^^^^^^^^^^^
  File "C:\Users\SAMURAI\PycharmProjects\soc_reports\.venv\Lib\site-packages\django\utils\functional.py", line 47, in __get__
    res = instance.__dict__[self.name] = self.func(instance)
                                         ~~~~~~~~~^^^^^^^^^^
  File "C:\Users\SAMURAI\PycharmProjects\soc_reports\.venv\Lib\site-packages\django\core\paginator.py", line 110, in count
    return c()
  File "C:\Users\SAMURAI\PycharmProjects\soc_reports\.venv\Lib\site-packages\django\db\models\query.py", line 604, in count
    return self.query.get_count(using=self.db)
           ~~~~~~~~~~~~~~~~~~~~^^^^^^^^^^^^^^^
  File "C:\Users\SAMURAI\PycharmProjects\soc_reports\.venv\Lib\site-packages\django\db\models\sql\query.py", line 644, in get_count
    return obj.get_aggregation(using, {"__count": Count("*")})["__count"]
           ~~~~~~~~~~~~~~~~~~~^^^^^^^^^^^^^^^^^^^^^^^^^^^^^^^^
  File "C:\Users\SAMURAI\PycharmProjects\soc_reports\.venv\Lib\site-packages\django\db\models\sql\query.py", line 626, in get_aggregation
    result = compiler.execute_sql(SINGLE)
  File "C:\Users\SAMURAI\PycharmProjects\soc_reports\.venv\Lib\site-packages\django\db\models\sql\compiler.py", line 1623, in execute_sql
    cursor.execute(sql, params)
    ~~~~~~~~~~~~~~^^^^^^^^^^^^^
  File "C:\Users\SAMURAI\PycharmProjects\soc_reports\.venv\Lib\site-packages\django\db\backends\utils.py", line 79, in execute
    return self._execute_with_wrappers(
           ~~~~~~~~~~~~~~~~~~~~~~~~~~~^
        sql, params, many=False, executor=self._execute
        ^^^^^^^^^^^^^^^^^^^^^^^^^^^^^^^^^^^^^^^^^^^^^^^
    )
    ^
  File "C:\Users\SAMURAI\PycharmProjects\soc_reports\.venv\Lib\site-packages\django\db\backends\utils.py", line 92, in _execute_with_wrappers
    return executor(sql, params, many, context)
  File "C:\Users\SAMURAI\PycharmProjects\soc_reports\.venv\Lib\site-packages\django\db\backends\utils.py", line 100, in _execute
    with self.db.wrap_database_errors:
         ^^^^^^^^^^^^^^^^^^^^^^^^^^^^
  File "C:\Users\SAMURAI\PycharmProjects\soc_reports\.venv\Lib\site-packages\django\db\utils.py", line 91, in __exit__
    raise dj_exc_value.with_traceback(traceback) from exc_value
  File "C:\Users\SAMURAI\PycharmProjects\soc_reports\.venv\Lib\site-packages\django\db\backends\utils.py", line 105, in _execute
    return self.cursor.execute(sql, params)
           ~~~~~~~~~~~~~~~~~~~^^^^^^^^^^^^^
  File "C:\Users\SAMURAI\PycharmProjects\soc_reports\.venv\Lib\site-packages\django\db\backends\sqlite3\base.py", line 360, in execute
    return super().execute(query, params)
           ~~~~~~~~~~~~~~~^^^^^^^^^^^^^^^
django.db.utils.OperationalError: no such table: db_logger_statuslog
2025-07-23 17:43:19,064 django.server ERROR    "GET /admin/db_logger/statuslog/ HTTP/1.1" 500 145
2025-07-23 17:43:39,407 django.request WARNING  Not Found: /static/admin/js/vendor/jquery/jquery.min.js
2025-07-23 17:43:39,408 django.request WARNING  Not Found: /static/admin/js/vendor/xregexp/xregexp.min.js
2025-07-23 17:43:39,409 django.server WARNING  "GET /static/admin/js/vendor/jquery/jquery.min.js HTTP/1.1" 404 179
2025-07-23 17:43:39,409 django.server WARNING  "GET /static/admin/js/vendor/xregexp/xregexp.min.js HTTP/1.1" 404 179
2025-07-23 17:44:04,213 django.request ERROR    Internal Server Error: /
Traceback (most recent call last):
  File "C:\Users\SAMURAI\PycharmProjects\soc_reports\.venv\Lib\site-packages\django\core\handlers\exception.py", line 55, in inner
    response = get_response(request)
  File "C:\Users\SAMURAI\PycharmProjects\soc_reports\.venv\Lib\site-packages\django\core\handlers\base.py", line 197, in _get_response
    response = wrapped_callback(request, *callback_args, **callback_kwargs)
  File "C:\Users\SAMURAI\PycharmProjects\soc_reports\reports\views.py", line 51, in report_create_view
    report.user = request.user
    ^^^^^^^^^^^
  File "C:\Users\SAMURAI\PycharmProjects\soc_reports\.venv\Lib\site-packages\django\db\models\fields\related_descriptors.py", line 288, in __set__
    raise ValueError(
    ...<7 lines>...
    )
ValueError: Cannot assign "<SimpleLazyObject: <django.contrib.auth.models.AnonymousUser object at 0x0000025268206210>>": "Report.user" must be a "CustomUser" instance.
2025-07-23 17:44:04,218 django.server ERROR    "POST / HTTP/1.1" 500 145
2025-07-23 17:44:15,930 django.request WARNING  Not Found: /static/admin/js/vendor/xregexp/xregexp.min.js
2025-07-23 17:44:15,930 django.request WARNING  Not Found: /static/admin/js/vendor/jquery/jquery.min.js
2025-07-23 17:44:15,930 django.server WARNING  "GET /static/admin/js/vendor/xregexp/xregexp.min.js HTTP/1.1" 404 179
2025-07-23 17:44:15,931 django.server WARNING  "GET /static/admin/js/vendor/jquery/jquery.min.js HTTP/1.1" 404 179
2025-07-23 17:44:17,734 django.request WARNING  Not Found: /static/admin/js/vendor/jquery/jquery.min.js
2025-07-23 17:44:17,734 django.request WARNING  Not Found: /static/admin/js/vendor/xregexp/xregexp.min.js
2025-07-23 17:44:17,734 django.server WARNING  "GET /static/admin/js/vendor/jquery/jquery.min.js HTTP/1.1" 404 179
2025-07-23 17:44:17,735 django.server WARNING  "GET /static/admin/js/vendor/xregexp/xregexp.min.js HTTP/1.1" 404 179
2025-07-23 17:51:36,479 django.request WARNING  Not Found: /static/admin/js/vendor/jquery/jquery.min.js
2025-07-23 17:51:36,480 django.request WARNING  Not Found: /static/admin/js/vendor/xregexp/xregexp.min.js
2025-07-23 17:51:36,481 django.server WARNING  "GET /static/admin/js/vendor/xregexp/xregexp.min.js HTTP/1.1" 404 179
2025-07-23 17:51:36,481 django.server WARNING  "GET /static/admin/js/vendor/jquery/jquery.min.js HTTP/1.1" 404 179
2025-07-23 17:57:11,435 django.request WARNING  Not Found: /static/admin/js/vendor/jquery/jquery.min.js
2025-07-23 17:57:11,436 django.request WARNING  Not Found: /static/admin/js/vendor/xregexp/xregexp.min.js
2025-07-23 17:57:11,437 django.server WARNING  "GET /static/admin/js/vendor/jquery/jquery.min.js HTTP/1.1" 404 179
2025-07-23 17:57:11,442 django.server WARNING  "GET /static/admin/js/vendor/xregexp/xregexp.min.js HTTP/1.1" 404 179
2025-07-23 17:57:13,241 django.request WARNING  Not Found: /static/admin/js/vendor/jquery/jquery.min.js
2025-07-23 17:57:13,242 django.request WARNING  Not Found: /static/admin/js/vendor/xregexp/xregexp.min.js
2025-07-23 17:57:13,243 django.server WARNING  "GET /static/admin/js/vendor/jquery/jquery.min.js HTTP/1.1" 404 179
2025-07-23 17:57:13,245 django.server WARNING  "GET /static/admin/js/vendor/xregexp/xregexp.min.js HTTP/1.1" 404 179
2025-07-23 17:59:22,292 django.request WARNING  Not Found: /static/admin/js/vendor/jquery/jquery.min.js
2025-07-23 17:59:22,292 django.server WARNING  "GET /static/admin/js/vendor/jquery/jquery.min.js HTTP/1.1" 404 179
2025-07-23 17:59:22,294 django.request WARNING  Not Found: /static/admin/js/vendor/xregexp/xregexp.min.js
2025-07-23 17:59:22,294 django.server WARNING  "GET /static/admin/js/vendor/xregexp/xregexp.min.js HTTP/1.1" 404 179
2025-07-23 18:03:50,002 django.request WARNING  Not Found: /accounts/login/
2025-07-23 18:03:50,003 django.server WARNING  "GET /accounts/login/?next=/ HTTP/1.1" 404 179
2025-07-23 18:03:54,671 django.request WARNING  Not Found: /accounts/login/
2025-07-23 18:03:54,672 django.server WARNING  "GET /accounts/login/?next=/ HTTP/1.1" 404 179
2025-07-23 18:03:58,007 django.request WARNING  Not Found: /accounts/login/
2025-07-23 18:03:58,007 django.server WARNING  "GET /accounts/login/?next=/ HTTP/1.1" 404 179
2025-07-23 18:04:41,903 django.request WARNING  Not Found: /accounts/login/
2025-07-23 18:04:41,904 django.server WARNING  "GET /accounts/login/?next=/ HTTP/1.1" 404 179
2025-07-23 18:04:42,526 django.request WARNING  Not Found: /accounts/login/
2025-07-23 18:04:42,526 django.server WARNING  "GET /accounts/login/?next=/ HTTP/1.1" 404 179
2025-07-23 18:04:44,695 django.request WARNING  Not Found: /user.login
2025-07-23 18:04:44,695 django.server WARNING  "GET /user.login?next=/ HTTP/1.1" 404 179
2025-07-23 18:04:55,081 django.request ERROR    Internal Server Error: /
Traceback (most recent call last):
  File "C:\Users\SAMURAI\PycharmProjects\soc_reports\.venv\Lib\site-packages\django\core\handlers\exception.py", line 55, in inner
    response = get_response(request)
  File "C:\Users\SAMURAI\PycharmProjects\soc_reports\.venv\Lib\site-packages\django\core\handlers\base.py", line 197, in _get_response
    response = wrapped_callback(request, *callback_args, **callback_kwargs)
  File "C:\Users\SAMURAI\PycharmProjects\soc_reports\.venv\Lib\site-packages\django\contrib\auth\decorators.py", line 60, in _view_wrapper
    return _redirect_to_login(request)
  File "C:\Users\SAMURAI\PycharmProjects\soc_reports\.venv\Lib\site-packages\django\contrib\auth\decorators.py", line 24, in _redirect_to_login
    resolved_login_url = resolve_url(login_url or settings.LOGIN_URL)
  File "C:\Users\SAMURAI\PycharmProjects\soc_reports\.venv\Lib\site-packages\django\shortcuts.py", line 184, in resolve_url
    return reverse(to, args=args, kwargs=kwargs)
  File "C:\Users\SAMURAI\PycharmProjects\soc_reports\.venv\Lib\site-packages\django\urls\base.py", line 98, in reverse
    resolved_url = resolver._reverse_with_prefix(view, prefix, *args, **kwargs)
  File "C:\Users\SAMURAI\PycharmProjects\soc_reports\.venv\Lib\site-packages\django\urls\resolvers.py", line 831, in _reverse_with_prefix
    raise NoReverseMatch(msg)
django.urls.exceptions.NoReverseMatch: Reverse for 'login' not found. 'login' is not a valid view function or pattern name.
2025-07-23 18:04:55,148 django.server ERROR    "GET / HTTP/1.1" 500 145
